Workbook

Sheet Лист1
A1: тело 1 | B1: хвост top 1 | C1: хвост bot 1 | D1: bull/bear | E1: Profit ++ | F1: Type | G1: Бар | H1: % ТЕЛА | I1: % top | J1: % bot | K1: могло бы быть
A2: 105 | B2: 87 | C2: 50 | D2: + | E2: 400 | F2: + | G2: =Лист1!$A2+Лист1!$B2+Лист1!$C2 -> 242 | H2: =Лист1!$A2/G2*100 -> 43.38843 | I2: =Лист1!$B2/G2*100 -> 35.950413 | J2: =Лист1!$C2/G2*100 -> 20.661157
A3: 89 | B3: 76 | C3: 34 | D3: + | E3: - | F3: - | G3: =Лист1!$A3+Лист1!$B3+Лист1!$C3 -> 199 | H3: =Лист1!$A3/G3*100 -> 44.723618 | I3: =Лист1!$B3/G3*100 -> 38.190955 | J3: =Лист1!$C3/G3*100 -> 17.085427 | S3: убрать зависимомсть 3 свечи от тренда
A4: 33 | B4: 41 | C4: 74 | D4: - | E4: - | F4: - | G4: =Лист1!$A4+Лист1!$B4+Лист1!$C4 -> 148 | H4: =Лист1!$A4/G4*100 -> 22.297297 | I4: =Лист1!$B4/G4*100 -> 27.702703 | J4: =Лист1!$C4/G4*100 -> 50 | S4: убрать зависимость 1-2 свеча расхождения
A5: 216 | B5: 25 | C5: 43 | D5: + | E5: - | F5: - | G5: =Лист1!$A5+Лист1!$B5+Лист1!$C5 -> 284 | H5: =Лист1!$A5/G5*100 -> 76.056338 | I5: =Лист1!$B5/G5*100 -> 8.8028169 | J5: =Лист1!$C5/G5*100 -> 15.140845 | S5: ограничить ибаланс не больше 600
A6: 20 | B6: 105 | C6: 134 | D6: + | E6: 800 | F6: + | G6: =Лист1!$A6+Лист1!$B6+Лист1!$C6 -> 259 | H6: =Лист1!$A6/G6*100 -> 7.7220077 | I6: =Лист1!$B6/G6*100 -> 40.540541 | J6: =Лист1!$C6/G6*100 -> 51.737452 | S6: попробывать сделать имбаланс в 150 пунктов
A7: 190 | B7: 133 | C7: 65 | D7: + | E7: - | F7: - | G7: =Лист1!$A7+Лист1!$B7+Лист1!$C7 -> 388 | H7: =Лист1!$A7/G7*100 -> 48.969072 | I7: =Лист1!$B7/G7*100 -> 34.278351 | J7: =Лист1!$C7/G7*100 -> 16.752577 | S7: трайлинг стоп сделать с фиксацией на 800 пунктов
A8: 63 | B8: 109 | C8: 39 | D8: + | E8: - | F8: - | G8: =Лист1!$A8+Лист1!$B8+Лист1!$C8 -> 211 | H8: =Лист1!$A8/G8*100 -> 29.85782 | I8: =Лист1!$B8/G8*100 -> 51.658768 | J8: =Лист1!$C8/G8*100 -> 18.483412 | S8: если нижний хвост = 0 то исключаем
A9: 91 | B9: 54 | C9: 76 | D9: - | E9: -10 | F9: + | G9: =Лист1!$A9+Лист1!$B9+Лист1!$C9 -> 221 | H9: =Лист1!$A9/G9*100 -> 41.176471 | I9: =Лист1!$B9/G9*100 -> 24.434389 | J9: =Лист1!$C9/G9*100 -> 34.38914
A10: 98 | B10: 76 | C10: 0 | D10: + | E10: - | F10: - | G10: =Лист1!$A10+Лист1!$B10+Лист1!$C10 -> 174 | H10: =Лист1!$A10/G10*100 -> 56.321839 | I10: =Лист1!$B10/G10*100 -> 43.678161 | J10: =Лист1!$C10/G10*100 -> 0 | K10: 200
A11: 220 | B11: 180 | C11: 96 | D11: - | E11: - | F11: - | G11: =Лист1!$A11+Лист1!$B11+Лист1!$C11 -> 496 | H11: =Лист1!$A11/G11*100 -> 44.354839 | I11: =Лист1!$B11/G11*100 -> 36.290323 | J11: =Лист1!$C11/G11*100 -> 19.354839
A12: 50 | B12: 26 | C12: 157 | D12: + | E12: - | F12: - | G12: =Лист1!$A12+Лист1!$B12+Лист1!$C12 -> 233 | H12: =Лист1!$A12/G12*100 -> 21.459227 | I12: =Лист1!$B12/G12*100 -> 11.158798 | J12: =Лист1!$C12/G12*100 -> 67.381974
A13: 20 | B13: 132 | C13: 24 | D13: - | E13: - | F13: - | G13: =Лист1!$A13+Лист1!$B13+Лист1!$C13 -> 176 | H13: =Лист1!$A13/G13*100 -> 11.363636 | I13: =Лист1!$B13/G13*100 -> 75 | J13: =Лист1!$C13/G13*100 -> 13.636364 | S13: поробовать рассчитать тоже самое только параметр volume сосмещением в один бар и должен идти на уменьшение либо смена направления у бара 1
A14: 60 | B14: 17 | C14: 110 | D14: + | E14: - | F14: - | G14: =Лист1!$A14+Лист1!$B14+Лист1!$C14 -> 187 | H14: =Лист1!$A14/G14*100 -> 32.085561 | I14: =Лист1!$B14/G14*100 -> 9.0909091 | J14: =Лист1!$C14/G14*100 -> 58.823529 | S14: или 1 свеча медвежья
A15: 38 | B15: 60 | C15: 23 | D15: + | E15: - | F15: - | G15: =Лист1!$A15+Лист1!$B15+Лист1!$C15 -> 121 | H15: =Лист1!$A15/G15*100 -> 31.404959 | I15: =Лист1!$B15/G15*100 -> 49.586777 | J15: =Лист1!$C15/G15*100 -> 19.008264
A16: 201 | B16: 78 | C16: 25 | D16: + | E16: 700 | F16: + | G16: =Лист1!$A16+Лист1!$B16+Лист1!$C16 -> 304 | H16: =Лист1!$A16/G16*100 -> 66.118421 | I16: =Лист1!$B16/G16*100 -> 25.657895 | J16: =Лист1!$C16/G16*100 -> 8.2236842
A17: 104 | B17: 78 | C17: 8 | D17: + | E17: 1500 | F17: + | G17: =Лист1!$A17+Лист1!$B17+Лист1!$C17 -> 190 | H17: =Лист1!$A17/G17*100 -> 54.736842 | I17: =Лист1!$B17/G17*100 -> 41.052632 | J17: =Лист1!$C17/G17*100 -> 4.2105263
A18: 63 | B18: 166 | C18: 1 | D18: + | E18: - | F18: - | G18: =Лист1!$A18+Лист1!$B18+Лист1!$C18 -> 230 | H18: =Лист1!$A18/G18*100 -> 27.391304 | I18: =Лист1!$B18/G18*100 -> 72.173913 | J18: =Лист1!$C18/G18*100 -> 0.43478261
A19: 27 | B19: 6 | C19: 153 | D19: - | E19: 200 | F19: + | G19: =Лист1!$A19+Лист1!$B19+Лист1!$C19 -> 186 | H19: =Лист1!$A19/G19*100 -> 14.516129 | I19: =Лист1!$B19/G19*100 -> 3.2258065 | J19: =Лист1!$C19/G19*100 -> 82.258065
A20: 114 | B20: 75 | C20: 8 | D20: + | E20: - | F20: - | G20: =Лист1!$A20+Лист1!$B20+Лист1!$C20 -> 197 | H20: =Лист1!$A20/G20*100 -> 57.86802 | I20: =Лист1!$B20/G20*100 -> 38.071066 | J20: =Лист1!$C20/G20*100 -> 4.0609137
A21: 53 | B21: 75 | C21: 65 | D21: + | E21: - | F21: - | G21: =Лист1!$A21+Лист1!$B21+Лист1!$C21 -> 193 | H21: =Лист1!$A21/G21*100 -> 27.46114 | I21: =Лист1!$B21/G21*100 -> 38.860104 | J21: =Лист1!$C21/G21*100 -> 33.678756
A22: 35 | B22: 71 | C22: 27 | D22: + | E22: 100 | F22: + | G22: =Лист1!$A22+Лист1!$B22+Лист1!$C22 -> 133 | H22: =Лист1!$A22/G22*100 -> 26.315789 | I22: =Лист1!$B22/G22*100 -> 53.383459 | J22: =Лист1!$C22/G22*100 -> 20.300752
A23: 285 | B23: 156 | C23: 56 | D23: + | E23: - | F23: - | G23: =Лист1!$A23+Лист1!$B23+Лист1!$C23 -> 497 | H23: =Лист1!$A23/G23*100 -> 57.344064 | I23: =Лист1!$B23/G23*100 -> 31.38833 | J23: =Лист1!$C23/G23*100 -> 11.267606 | K23: 300
A24: 331 | B24: 88 | C24: 8 | D24: + | E24: - | F24: - | G24: =Лист1!$A24+Лист1!$B24+Лист1!$C24 -> 427 | H24: =Лист1!$A24/G24*100 -> 77.517564 | I24: =Лист1!$B24/G24*100 -> 20.608899 | J24: =Лист1!$C24/G24*100 -> 1.8735363 | K24: 250 | T24: 230
A25: 215 | B25: 9 | C25: 30 | D25: + | E25: 400 | F25: + | G25: =Лист1!$A25+Лист1!$B25+Лист1!$C25 -> 254 | H25: =Лист1!$A25/G25*100 -> 84.645669 | I25: =Лист1!$B25/G25*100 -> 3.5433071 | J25: =Лист1!$C25/G25*100 -> 11.811024
A26: 22 | B26: 95 | C26: 165 | D26: + | E26: + | F26: + | G26: =Лист1!$A26+Лист1!$B26+Лист1!$C26 -> 282 | H26: =Лист1!$A26/G26*100 -> 7.8014184 | I26: =Лист1!$B26/G26*100 -> 33.687943 | J26: =Лист1!$C26/G26*100 -> 58.510638
A27: 36 | B27: 215 | C27: 50 | D27: - | E27: 400 | F27: + | G27: =Лист1!$A27+Лист1!$B27+Лист1!$C27 -> 301 | H27: =Лист1!$A27/G27*100 -> 11.960133 | I27: =Лист1!$B27/G27*100 -> 71.428571 | J27: =Лист1!$C27/G27*100 -> 16.611296
A28: 18 | B28: 110 | C28: 168 | D28: - | E28: 400 | F28: - | G28: =Лист1!$A28+Лист1!$B28+Лист1!$C28 -> 296 | H28: =Лист1!$A28/G28*100 -> 6.0810811 | I28: =Лист1!$B28/G28*100 -> 37.162162 | J28: =Лист1!$C28/G28*100 -> 56.756757
A29: 134 | B29: 67 | C29: 45 | D29: + | E29: - | F29: - | G29: =Лист1!$A29+Лист1!$B29+Лист1!$C29 -> 246 | H29: =Лист1!$A29/G29*100 -> 54.471545 | I29: =Лист1!$B29/G29*100 -> 27.235772 | J29: =Лист1!$C29/G29*100 -> 18.292683
A30: 77 | B30: 27 | C30: 0 | D30: + | E30: - | F30: - | G30: =Лист1!$A30+Лист1!$B30+Лист1!$C30 -> 104 | H30: =Лист1!$A30/G30*100 -> 74.038462 | I30: =Лист1!$B30/G30*100 -> 25.961538 | J30: =Лист1!$C30/G30*100 -> 0
A31: 107 | B31: 61 | C31: 21 | D31: + | E31: 100 | F31: + | G31: =Лист1!$A31+Лист1!$B31+Лист1!$C31 -> 189 | H31: =Лист1!$A31/G31*100 -> 56.613757 | I31: =Лист1!$B31/G31*100 -> 32.275132 | J31: =Лист1!$C31/G31*100 -> 11.111111
A32: 303 | B32: 233 | C32: 69 | D32: + | E32: 1000 | F32: + | G32: =Лист1!$A32+Лист1!$B32+Лист1!$C32 -> 605 | H32: =Лист1!$A32/G32*100 -> 50.082645 | I32: =Лист1!$B32/G32*100 -> 38.512397 | J32: =Лист1!$C32/G32*100 -> 11.404959
A33: 169 | B33: 38 | C33: 69 | D33: + | E33: 1000 | F33: + | G33: =Лист1!$A33+Лист1!$B33+Лист1!$C33 -> 276 | H33: =Лист1!$A33/G33*100 -> 61.231884 | I33: =Лист1!$B33/G33*100 -> 13.768116 | J33: =Лист1!$C33/G33*100 -> 25
A34: 56 | B34: 310 | C34: 25 | D34: - | E34: - | F34: - | G34: =Лист1!$A34+Лист1!$B34+Лист1!$C34 -> 391 | H34: =Лист1!$A34/G34*100 -> 14.322251 | I34: =Лист1!$B34/G34*100 -> 79.283887 | J34: =Лист1!$C34/G34*100 -> 6.3938619
A35: 196 | B35: 37 | C35: 28 | D35: + | E35: 500 | F35: + | G35: =Лист1!$A35+Лист1!$B35+Лист1!$C35 -> 261 | H35: =Лист1!$A35/G35*100 -> 75.095785 | I35: =Лист1!$B35/G35*100 -> 14.176245 | J35: =Лист1!$C35/G35*100 -> 10.727969
A36: 108 | B36: 87 | C36: 219 | D36: - | E36: - | F36: - | G36: =Лист1!$A36+Лист1!$B36+Лист1!$C36 -> 414 | H36: =Лист1!$A36/G36*100 -> 26.086957 | I36: =Лист1!$B36/G36*100 -> 21.014493 | J36: =Лист1!$C36/G36*100 -> 52.898551
A37: 55 | B37: 64 | C37: 172 | D37: + | E37: - | F37: - | G37: =Лист1!$A37+Лист1!$B37+Лист1!$C37 -> 291 | H37: =Лист1!$A37/G37*100 -> 18.900344 | I37: =Лист1!$B37/G37*100 -> 21.993127 | J37: =Лист1!$C37/G37*100 -> 59.106529 | K37: 350
A38: 9 | B38: 208 | C38: 48 | D38: - | E38: - | F38: - | G38: =Лист1!$A38+Лист1!$B38+Лист1!$C38 -> 265 | H38: =Лист1!$A38/G38*100 -> 3.3962264 | I38: =Лист1!$B38/G38*100 -> 78.490566 | J38: =Лист1!$C38/G38*100 -> 18.113208 | K38: 150
A39: 214 | B39: 67 | C39: 57 | D39: + | E39: + | F39: + | G39: =Лист1!$A39+Лист1!$B39+Лист1!$C39 -> 338 | H39: =Лист1!$A39/G39*100 -> 63.313609 | I39: =Лист1!$B39/G39*100 -> 19.822485 | J39: =Лист1!$C39/G39*100 -> 16.863905
A40: 414 | B40: 41 | C40: 129 | D40: + | E40: - | F40: - | G40: =Лист1!$A40+Лист1!$B40+Лист1!$C40 -> 584 | H40: =Лист1!$A40/G40*100 -> 70.890411 | I40: =Лист1!$B40/G40*100 -> 7.0205479 | J40: =Лист1!$C40/G40*100 -> 22.089041
...
