Workbook

Sheet Общее
A1: Наименование затрат | B1: План Март | C1: Факт Март | D1: План Апрель | E1: Факт Апрель | F1: План Май | G1: Факт Май | H1: План Октябрь | I1: Факт Октябрь | J1: План Ноябрь | K1: Факт Ноябрь | L1: План Декабрь | M1: Факт Декабрь | N1: План Январь | O1: Факт Январь | P1: План Февраль | Q1: Факт Февраль | R1: План Март | S1: Факт Март
A2: Коммунальные платежи: | B2: =SUM(B3:B6) -> 137 | C2: =SUM(C3:C6) -> 184.67 | D2: =SUM(D3:D6) -> 167.5 | E2: =SUM(E3:E6) -> 155.85 | F2: =SUM(F3:F6) -> 167.5 | G2: =SUM(G3:G6) -> 142.8 | H2: =SUM(H3:H6) -> 167.5 | I2: =SUM(I3:I6) -> 142.42 | ... S2: =SUM(S3:S6) -> 0
A3: -коммуналка | B3: 70 | C3: 98.5 | D3: 90 | E3: 86.77 | F3: 90 | G3: 82.34 | H3: 90 | I3: 58.85 | J3: 90 | K3: 59.05 | L3: 90 | M3: 73.42 | N3: 90 | P3: 90 | R3: 90
A4: -свет | B4: 30 | C4: 32.98 | D4: 30 | E4: 26.89 | F4: 30 | G4: 24.36 | H4: 30 | I4: 32.47 | J4: 30 | K4: 28.16 | L4: 30 | N4: 30 | P4: 30 | R4: 30
A5: -газ | B5: 2 | C5: 2.19 | D5: 2.5 | E5: 2.19 | F5: 2.5 | G5: 1.1 | H5: 2.5 | I5: 1.1 | J5: 2.5 | K5: 1.1 | L5: 2.5 | N5: 2.5 | P5: 2.5 | R5: 2.5
A6: -Zala | B6: 35 | C6: =35+10+6 -> 51 | D6: 45 | E6: 40 | F6: 45 | G6: 35 | H6: 45 | I6: 50 | J6: 45 | K6: 35 | L6: 45 | M6: 45 | N6: 45 | P6: 45 | R6: 45
A7: Телефоны абонентская: | B7: =SUM(B8:B10) -> 85 | C7: =SUM(C8:C10) -> 118 | D7: =SUM(D8:D10) -> 120 | E7: =SUM(E8:E10) -> 133.33 | F7: =SUM(F8:F10) -> 120 | G7: =SUM(G8:G10) -> 105 | H7: =SUM(H8:H10) -> 120 | I7: =SUM(I8:I10) -> 115 | ... S7: =SUM(S8:S10) -> 0
A8: -Вова | B8: 45 | C8: 35 | D8: 40 | E8: 35 | F8: 40 | G8: 35 | H8: 40 | I8: 45 | J8: 40 | K8: 40 | L8: 45 | M8: 45 | N8: 40 | P8: 40 | R8: 40
A9: -Таня МТС | B9: 20 | C9: =20+6+10+6 -> 42 | D9: 40 | E9: =45+7.83+5.5+5 -> 63.33 | F9: 40 | G9: 35 | H9: 40 | I9: 35 | J9: 40 | K9: 35 | L9: 40 | M9: 10 | N9: 40 | P9: 40 | R9: 40
A10: -Паша МТС | B10: 20 | C10: =20+16+5 -> 41 | D10: 40 | E10: =30+5 -> 35 | F10: 40 | G10: 35 | H10: 40 | I10: 35 | J10: 40 | K10: 35 | L10: 40 | M10: 35 | N10: 40 | P10: 40 | R10: 40
A11: Квартира | B11: =300*3.24 -> 972 | C11: =811.25+162.25 -> 973.5 | D11: 975 | E11: =979.5 -> 979.5 | F11: 975 | G11: 981.23 | H11: 987.46 | I11: =300*3.215 -> 964.5 | J11: 987.46 | K11: =300*3.27 -> 981 | L11: 987.46 | M11: =280*3.52 -> 985.6 | N11: 987.46 | P11: 987.46 | R11: 987.46
A12: Квартира строительство: | B12: 40 | C12: 40 | D12: =SUM(D13:D14) -> 40 | E12: =SUM(E13:E14) -> 40.75 | F12: =SUM(F13:F14) -> 40.75 | G12: =SUM(G13:G14) -> 40.75 | H12: =SUM(H13:H14) -> 40.75 | I12: =SUM(I13:I14) -> 40.75 | J12: =SUM(J13:J14) -> 40.75 | K12: =SUM(K13:K14) -> 40.75 | ... S12: =SUM(S13:S14) -> 0
A13: -членские | B13: 40 | C13: 40 | D13: 40 | E13: 40.75 | F13: 40.75 | G13: 40.75 | H13: 40.75 | I13: 40.75 | J13: 40.75 | K13: 40.75 | L13: 40.75 | M13: 40.75 | N13: 40.75 | P13: 40.75 | R13: 40.75
A14: -паевые | B14: 0
A15: Рассрочки: | B15: =SUM(B16:B20) -> 537.62 | C15: =SUM(C16:C20) -> 537.79 | D15: =SUM(D16:D20) -> 540.03 | E15: =SUM(E16:E20) -> 571.59 | F15: =SUM(F16:F20) -> 574.53 | G15: =SUM(G16:G20) -> 559.37 | H15: =SUM(H16:H20) -> 227.35 | I15: =SUM(I16:I20) -> 206.7075 | ... S15: =SUM(S16:S20) -> 0
A16: -телефон iphone | B16: 190 | C16: 190 | D16: 190 | E16: 190 | F16: 190 | G16: 190
A17: -кредит Мама | B17: 132.78 | C17: 132.78 | D17: 132.78 | E17: 132.78 | F17: 132.78 | G17: 132.82
A18: - лайф Мама | B18: 25 | C18: 25 | D18: 25 | E18: 25 | F18: 25 | G18: 25
A19: -skillbox | B19: 176.75 | C19: 176.92 | D19: 176.75 | E19: 177.21 | F19: 176.75 | G19: 177.05 | H19: 177.35 | I19: 177.22 | J19: 177.5 | K19: 177.49 | L19: 177.35 | M19: 177.23 | N19: 177.35 | P19: 177.35 | R19: 177.35
A20: -подписки | B20: 13.09 | C20: 13.09 | D20: 15.5 | E20: =4*3.24+2.24+2.24+2.24+2.24+16.5+8.18 -> 46.6 | F20: 50 | G20: =2.24+13.05+2.24+16.97 -> 34.5 | H20: 50 | I20: =(3.99*3.215)*2+(1.19*3.22) -> 29.4875 | J20: 50 | K20: =2.24+(3.99*3.3)*2+2.24+11.99+4 -> 46.804 | L20: 50 | M20: =2.24+2.24+(3.99*3.46) -> 18.2854 | N20: 50 | P20: 50 | R20: 50
A21: Кружки: | B21: =SUM(B22:B26) -> 775 | C21: =SUM(C22:C26) -> 570 | D21: =SUM(D22:D26) -> 480 | E21: =SUM(E22:E26) -> 292.38 | F21: =SUM(F22:F26) -> 480 | G21: =SUM(G22:G26) -> 174 | H21: =SUM(H22:H26) -> 315 | I21: =SUM(I22:I26) -> 375.35 | ... S21: =SUM(S22:S26) -> 0
A22: -таэквондо | B22: =85+300 -> 385 | C22: =(50.45+11.5+7.2+14.05)+30+185+25+85 -> 408.2 | D22: =85+25 -> 110 | E22: =25+85.75 -> 110.75 | F22: =85+25 -> 110 | H22: 85 | I22: =70 -> 70 | J22: 85.75 | K22: =85.75+25 -> 110.75 | L22: 100 | N22: =85+25 -> 110 | P22: =85+25 -> 110 | R22: =85+25 -> 110
A23: -карманные расходы Паша | B23: 120 | C23: =2.6+10+5+10+20+3.2+27+3+20+4 -> 104.8 | D23: 100 | E23: =8+10+10+2.6+2.6+6.1+20+5+5+3.5+5+15+3+5+2.6 -> 103.4 | F23: 100 | G23: =20+4+10+10 -> 44 | H23: 50 | I23: =6.5+3+4+2.61+3+3+4+2.6+110+3+5+4 -> 150.71 | J23: 100 | K23: =3+3+3+3+5+7+3+5+2.6+2.6+5+10+5+7+2.6+2.6+5+5+7+10+2.6+3+4+3 -> 109 | L23: 125 | M23: =25+25 -> 50 | N23: 100 | P23: 100 | R23: 100
A24: -бассейн | G24: 100 | H24: 100 | I24: =34+34 -> 68 | J24: 136 | L24: 136 | N24: 100 | P24: 100 | R24: 100
A25: -питание | B25: 80 | C25: =20+17+20 -> 57 | D25: 80 | E25: =50+3.23+25 -> 78.23 | F25: 80 | G25: =30 -> 30 | H25: 80 | I25: =61.64+15+10 -> 86.64 | J25: 80 | K25: 70 | L25: 80 | M25: 80 | N25: 80 | P25: 80 | R25: 80
A26: -тренажерки | B26: 190 | D26: 190 | F26: 190
A27: Заправка | B27: =6*50 -> 300 | C27: =Заправка!A$33 -> 717.14 | D27: 400 | E27: =Заправка!B$33 -> 525.16 | F27: 400 | G27: =Заправка!C33 -> 350.13 | H27: 400 | I27: =Заправка!E33 -> 615.7 | J27: 500 | K27: =Заправка!G33 -> 532.43 | L27: 400 | M27: =Заправка!I33 -> 364.42 | N27: 400 | O27: =Заправка!K33 -> 0 | P27: 400 | Q27: =Заправка!M33 -> 0 | R27: 400 | S27: =Заправка!O33 -> 0
A28: Зайка)) | B28: 360 | C28: =Зайка!A$33 -> 232.32 | D28: 360 | E28: =Зайка!B$33 -> 104.76 | F28: 360 | G28: =Зайка!C33 -> 330.6 | H28: 360 | I28: =Зайка!E33 -> 162.84 | J28: 360 | K28: =Зайка!G33 -> 181.19 | L28: 360 | M28: =Зайка!I33 -> 77.87 | N28: 360 | O28: =Зайка!K33 -> 0 | P28: 360 | Q28: =Зайка!M33 -> 0 | R28: 360 | S28: =Зайка!O33 -> 0
A29: -шампунь
A30: -кондиционер для волос
A31: -кератин
A32: -умывашки)
A33: -маникюр
A34: -кофе обед
A35: Вовчик | F35: 100 | G35: =Вовчик!C33 -> 59.79 | H35: 261 | I35: =Вовчик!E33 -> 261 | J35: 100 | K35: =Вовчик!G33 -> 99 | L35: 100 | M35: =100+59.03 -> 159.03 | N35: 100 | O35: =Вовчик!K33 -> 0 | P35: 100 | Q35: =Вовчик!M33 -> 0 | R35: 100 | S35: =Вовчик!O33 -> 0
A36: Еда | B36: 700 | C36: =Еда!A$33 -> 719.42 | D36: 700 | E36: =Еда!B$33 -> 917.19 | F36: 700 | G36: =Еда!C33 -> 549.77 | H36: 700 | I36: =Еда!E33 -> 1155.33 | J36: 800 | K36: =Еда!G33 -> 1040.81 | L36: 900 | M36: =Еда!I33 -> 668.12 | N36: 700 | O36: =Еда!K33 -> 0 | P36: 700 | Q36: =Еда!M33 -> 0 | R36: 700 | S36: =Еда!O33 -> 0
A37: Машина | B37: =B$50*0.6 -> 1048.518 | C37: =50.4+120+39.93+6+620 -> 836.33 | D37: =$D$50*0.2 -> 333.422 | E37: =167+126 -> 293 | F37: =$D$50*0.2 -> 333.422 | H37: =H50*0.2 -> 151.388 | I37: 142.4 | J37: =J50*0.2 -> 212.208 | K37: =76.5+17 -> 93.5 | L37: =L50*0.2 -> 203.388 | M37: =162.6+50+15 -> 227.6 | N37: =N50*0.2 -> 254.588 | P37: =P50*0.2 -> 254.588 | R37: =R50*0.2 -> 254.588
A38: Одежда | B38: =B$50*0.2 -> 349.506 | C38: =Одежда!A$33 -> 158 | D38: =$D$50*0.2 -> 333.422 | E38: =Одежда!B$33 -> 1226.82 | F38: =$D$50*0.2 -> 333.422 | G38: =Одежда!C33 -> 36.57 | H38: =H50*0.4 -> 302.776 | I38: =Одежда!E33 -> 700 | J38: =J50*0.2 -> 212.208 | K38: =Одежда!G33 -> 977.93 | L38: =L50*0.2 -> 203.388 | M38: =Одежда!I33 -> 115 | N38: =N50*0.2 -> 254.588 | O38: =Одежда!K33 -> 0 | P38: =P50*0.2 -> 254.588 | Q38: =Одежда!M33 -> 0 | R38: =R50*0.2 -> 254.588 | S38: =Одежда!O33 -> 0
A39: Отдых | B39: =B$50*0.1 -> 174.753 | C39: =Отдых!A33 -> 138.16 | D39: =$D$50*0.2 -> 333.422 | E39: =Отдых!B33 -> 221.2 | F39: =$D$50*0.2 -> 333.422 | G39: =Отдых!D33 -> 0 | H39: =H50*0 -> 0 | I39: =Отдых!F33 -> 0 | J39: =J50*0.2 -> 212.208 | K39: =Отдых!G33 -> 256.22 | L39: =L50*0.2 -> 203.388 | N39: =N50*0.2 -> 254.588 | P39: =P50*0.2 -> 254.588 | R39: =R50*0.2 -> 254.588
A40: Отлажить | B40: =B$50*0 -> 0 | D40: =$D$50*0.1 -> 166.711 | F40: =$D$50*0.1 -> 166.711 | H40: =H50*0.3 -> 227.082 | J40: =J50*0.1 -> 106.104 | L40: =L50*0.1 -> 101.694 | N40: =N50*0.1 -> 127.294 | P40: =P50*0.1 -> 127.294 | R40: =R50*0.1 -> 127.294
...

Sheet Отдых
A1: март | B1: апрель | C1: май | D1: июнь | E1: октябрь | G1: ноябрь | I1: декабрь | K1: январь | M1: февраль | O1: март | Q1: апрель | S1: май | U1: июнь | W1: июль | Y1: август
A2: =35.15 -> 35.15 | C2: =10.8+100+6.03+5.3+12 -> 134.13 | I2: =62 -> 62
G6: =25.69+0.5 -> 26.19
B7: =42.5 -> 42.5
B8: =33+26.08+5.3 -> 64.38
G9: =42.5 -> 42.5
B11: =19.8+31.87+15.35 -> 67.02
A13: =16.18 -> 16.18
A14: =20.84 -> 20.84
B15: =16.5 -> 16.5
C21: =16+6+17.8 -> 39.8
I23: =28.38 -> 28.38
A24: =2.5+46+17.49 -> 65.99 | B24: =30.8 -> 30.8
G26: =2.9+26 -> 28.9 | I26: =11.59 -> 11.59
G28: =48.36 -> 48.36
G29: =6.2+24.07+80 -> 110.27 | I29: =33+1+2.5+2+2.5 -> 41
I30: =30+16 -> 46
A33: =SUM(A2:A32) -> 138.16 | B33: =SUM(B2:B32) -> 221.2 | C33: =SUM(C2:C32) -> 173.93 | D33: =SUM(D2:D32) -> 0 | E33: =SUM(E2:E32) -> 0 | G33: =SUM(G2:G32) -> 256.22 | I33: =SUM(I2:I32) -> 188.97 | K33: =SUM(K2:K32) -> 0 | M33: =SUM(M2:M32) -> 0 | O33: =SUM(O2:O32) -> 0 | Q33: =SUM(Q2:Q32) -> 0 | S33: =SUM(S2:S32) -> 0 | U33: =SUM(U2:U32) -> 0 | W33: =SUM(W2:W32) -> 0 | Y33: =SUM(Y2:Y32) -> 0

Sheet Еда
A1: март | B1: апрель | C1: май | D1: июнь | E1: октябрь | G1: ноябрь | I1: декабрь | K1: январь | M1: февраль | O1: март | Q1: апрель | S1: май | U1: июнь | W1: июль | Y1: август
A2: =1.9+12.4+8.99 -> 23.29 | B2: =35.21+5.3+9.44 -> 49.95 | E2: =10.67+10.12 -> 20.79 | G2: =63.49+6.2 -> 69.69 | I2: =27.91 -> 27.91
A3: =8.25 -> 8.25 | B3: =8.48+29.04+19.06 -> 56.58 | E3: =40.75 -> 40.75 | G3: =3.65+7.8+3.14+13+12.1+9.44+14.99 -> 64.12
A4: =44.65 -> 44.65 | B4: =34.14+1.42 -> 35.56 | C4: =5.35+63.07 -> 68.42 | E4: =23.16+14.58 -> 37.74 | G4: =4.41+1.82+4+13.95 -> 24.18
A5: =5.3+45.27 -> 50.57 | B5: =57.98+12.6 -> 70.58 | C5: =24.46 -> 24.46 | E5: =75.62 -> 75.62 | G5: =1.9+43.29 -> 45.19
B6: =66.1+4.66 -> 70.76 | C6: =6.91+6.57 -> 13.48 | E6: =9.6 -> 9.6 | G6: =55.63 -> 55.63
A7: 1.7 | B7: =27.66 -> 27.66 | E7: =7.05+1.87+35.15+19.36 -> 63.43 | G7: =6.2+23.21 -> 29.41
B8: =5.3 -> 5.3 | E8: =33.26 -> 33.26
A9: =5.3+9.02 -> 14.32 | B9: =29.32 -> 29.32 | E9: =8+6.2+38.98 -> 53.18 | G9: =7.89+15.62+2.86+6.1 -> 32.47
A10: =10.6+0.58 -> 11.18 | B10: =28.84+32.09 -> 60.93 | E10: =28.75+60.96 -> 89.71 | G10: =25.91 -> 25.91
A11: =1+5.71 -> 6.71 | E11: =30 -> 30
A12: =22.67+2.93+1.74+3.81 -> 31.15 | B12: =39.23 -> 39.23 | G12: =46.47 -> 46.47
A13: =2.7+0.3+4.67+0.44 -> 8.11 | B13: =3.2 -> 3.2 | G13: =16.32+2.65 -> 18.97
A14: =10.6 -> 10.6 | B14: =1.4 -> 1.4 | E14: =63 -> 63 | G14: =54.69 -> 54.69
A15: =7.39 -> 7.39 | B15: =5.3 -> 5.3 | G15: =8.5+27.98+0.72 -> 37.2
A16: =13.69+11.2 -> 24.89 | B16: =28.18 -> 28.18 | E16: =39.86 -> 39.86 | G16: =86.89 -> 86.89
A17: =53.52 -> 53.52 | B17: =2.75 -> 2.75 | G17: =6.2+12.7+30.6 -> 49.5
A18: =44.91+5.3 -> 50.21 | B18: =33.7 -> 33.7 | E18: =113.75+6.2 -> 119.95
A19: =7.73 -> 7.73 | C19: =4.6+96.71+3.99 -> 105.3 | E19: =37.94+37.71+10.5 -> 86.15 | G19: =32.86 -> 32.86
A20: =44.42 -> 44.42 | C20: =40.29+8.2+2.8+13.28+18 -> 82.57 | E20: =3.17+55.37+32.42 -> 90.96
B21: =5.8+42.15 -> 47.95 | C21: =9.25+2.43+40.49 -> 52.17 | G21: =33.46 -> 33.46 | I21: =31.74+6.2+33.39 -> 71.33
A22: =49.74+13.59 -> 63.33 | B22: =5.3+31.06 -> 36.36 | E22: 27.4 | G22: =6.2+35.03+14.92 -> 56.15 | I22: =81.01 -> 81.01
A23: =30.94+32.61+1.42 -> 64.97 | B23: =50 -> 50 | G23: =33.53 -> 33.53 | I23: =30.34+8.84+6.2+39.32+20+21.76 -> 126.46
B24: =5.3+50.66 -> 55.96 | C24: =2.15+10+43.27 -> 55.42 | E24: =67.92+11.8 -> 79.72 | G24: =28.45 -> 28.45 | I24: =18.79 -> 18.79
B25: =8.11+12.15 -> 20.26 | G25: =66.12 -> 66.12 | I25: =9.67+15.52 -> 25.19
A26: =42.34+4.32+23.95+26.69+4.43 -> 101.73 | B26: =24.62 -> 24.62 | C26: =26.56 -> 26.56 | E26: =5.9 -> 5.9 | G26: =56.77 -> 56.77 | I26: =6.2+17.21 -> 23.41
A27: =5.3 -> 5.3 | B27: =5.3+15 -> 20.3 | C27: =11.98 -> 11.98 | E27: =11.76+5.9+33.84 -> 51.5 | G27: =10.5+18.5+10.76+4.4 -> 44.16 | I27: =6.2 -> 6.2
A28: =24.25 -> 24.25 | B28: =58.65 -> 58.65 | C28: =1.35+60 -> 61.35 | E28: =2+11.8 -> 13.8 | G28: =6.2+11.39 -> 17.59 | I28: =28.82 -> 28.82
A29: =6.62 -> 6.62 | B29: =5.3+44.97 -> 50.27 | E29: =54.86+8+17.83 -> 80.69 | G29: =3.73+4.95 -> 8.68 | I29: =66.86 -> 66.86
A30: =5.3+49.23 -> 54.53 | C30: =48.06 -> 48.06 | E30: 42.32 | G30: =11.04+11.33 -> 22.37 | I30: =41.22+6.2 -> 47.42
B31: =32.42 -> 32.42 | G31: =0.35 -> 0.35 | I31: =115.94+28.78 -> 144.72
A33: =SUM(A2:A32) -> 719.42 | B33: =SUM(B2:B32) -> 917.19 | C33: =SUM(C2:C32) -> 549.77 | D33: =SUM(D2:D32) -> 0 | E33: =SUM(E2:E32) -> 1155.33 | G33: =SUM(G2:G32) -> 1040.81 | I33: =SUM(I2:I32) -> 668.12 | K33: =SUM(K2:K32) -> 0 | M33: =SUM(M2:M32) -> 0 | O33: =SUM(O2:O32) -> 0 | Q33: =SUM(Q2:Q32) -> 0 | S33: =SUM(S2:S32) -> 0 | U33: =SUM(U2:U32) -> 0 | W33: =SUM(W2:W32) -> 0 | Y33: =SUM(Y2:Y32) -> 0

Sheet Одежда
A1: март | B1: апрель | C1: май | D1: июнь | E1: октябрь | G1: ноябрь | I1: декабрь | K1: январь | M1: февраль | O1: март | Q1: апрель | S1: май | U1: июнь | W1: июль | Y1: август
C2: =36.57 -> 36.57
B7: =176.93+0.89+0.2 -> 178.02
B8: =143 -> 143 | G8: =199+192.44 -> 391.44
G16: =42.38 -> 42.38
G17: =140+260 -> 400
A18: =158 -> 158 | B18: 78.24 | E18: =700 -> 700
B21: 155.78
B24: =309 -> 309
G25: 144.11
B30: =40 -> 40 | I30: =115 -> 115
B31: =322.78 -> 322.78
A33: =SUM(A2:A32) -> 158 | B33: =SUM(B2:B32) -> 1226.82 | C33: =SUM(C2:C32) -> 36.57 | D33: =SUM(D2:D32) -> 0 | E33: =SUM(E2:E32) -> 700 | G33: =SUM(G2:G32) -> 977.93 | I33: =SUM(I2:I32) -> 115 | K33: =SUM(K2:K32) -> 0 | M33: =SUM(M2:M32) -> 0 | O33: =SUM(O2:O32) -> 0 | Q33: =SUM(Q2:Q32) -> 0 | S33: =SUM(S2:S32) -> 0 | U33: =SUM(U2:U32) -> 0 | W33: =SUM(W2:W32) -> 0 | Y33: =SUM(Y2:Y32) -> 0

Sheet Заправка
A1: март | B1: апрель | C1: май | D1: июнь | E1: октябрь | G1: ноябрь | I1: декабрь | K1: январь | M1: февраль | O1: март | Q1: апрель | S1: май | U1: июнь
A2: =6.75+5.84+0.04+9.98+1.04+2.64+2+13.28+50 -> 91.57 | G2: =60 -> 60 | I2: =64.58 -> 64.58
B3: =9.77+50.01 -> 59.78 | E3: =50 -> 50 | G3: =50 -> 50
C4: =17.3+50 -> 67.3 | G4: =5.92 -> 5.92
B5: =50 -> 50 | E5: =50 -> 50 | G5: =7.05 -> 7.05
C6: =60 -> 60 | E6: =20 -> 20
A7: =12.74+5+2.04+6.47+3.68+0.9 -> 30.83 | B7: =6.35 -> 6.35
A8: =8.43 -> 8.43 | B8: =10+2.75 -> 12.75 | E8: =1.8+5.59 -> 7.39
B9: =7.9+9.66 -> 17.56 | G9: =6.28 -> 6.28
A11: =1.75 -> 1.75 | B11: =8.38 -> 8.38 | E11: =0.9 -> 0.9
A12: =11.06+9.21 -> 20.27 | B12: 63
A13: =11.8 -> 11.8
E14: =60 -> 60 | G14: =6.85+0.9 -> 7.75
G15: =0.9+29.67 -> 30.57
A16: =8.42 -> 8.42 | B16: =18.7+0.4 -> 19.1 | E16: =64.58 -> 64.58
A17: =65+12 -> 77 | B17: =13.25+13.99 -> 27.24
B18: 6.79
B19: 60.4 | E19: =35.66+4 -> 39.66
A20: =10.2+70 -> 80.2 | C20: =18.06+1.83 -> 19.89 | E20: 65.99
B21: =50.01 -> 50.01 | E21: 11.71 | G21: =6.13 -> 6.13
A22: 50 | B22: =8.69 -> 8.69 | C22: 59.19 | E22: =15.2+55.91 -> 71.11 | G22: =58.38 -> 58.38 | I22: =61.86 -> 61.86
A23: 10 | C23: =15.77 -> 15.77 | E23: =46.15+57.5 -> 103.65 | I23: =120.15 -> 120.15
A24: =20.64+2+8.62+1.34+2+0.76+2+2.14+2+8.53 -> 50.03 | C24: =2.57+4.5 -> 7.07 | I24: =2.7 -> 2.7
A25: =11.89+5+24.87 -> 41.76
A26: =25.5+5.62 -> 31.12 | B26: =11.95 -> 11.95 | C26: =60.91 -> 60.91 | G26: =64.58 -> 64.58
A27: =2+7.04+16.48+10.44+10.48+5.87+0.92+2+9.45+1.43 -> 66.11 | E27: =2+11.42+2+5.29 -> 20.71 | G27: =41.28+6.2 -> 47.48
A28: =9.09+9.42+2+11.18+5.3 -> 36.99 | B28: =65.67 -> 65.67 | C28: =60 -> 60 | E28: =50 -> 50 | I28: =56.45 -> 56.45
A29: =10+1.18+12.03 -> 23.21 | G29: =4.87+60+1+9 -> 74.87 | I29: =11.99+10+8.89+10+3.83 -> 44.71
A30: =19.52+9.43+10+10+3.93+10+1.96+10+2.81 -> 77.65 | G30: =60.39 -> 60.39 | I30: =1.8+6+6.17 -> 13.97
B31: 57.49 | G31: =53.03 -> 53.03
A33: =SUM(A2:A32) -> 717.14 | B33: =SUM(B2:B32) -> 525.16 | C33: =SUM(C2:C32) -> 350.13 | D33: =SUM(D2:D32) -> 0 | E33: =SUM(E2:E32) -> 615.7 | G33: =SUM(G2:G32) -> 532.43 | I33: =SUM(I2:I32) -> 364.42 | K33: =SUM(K2:K32) -> 0 | M33: =SUM(M2:M32) -> 0 | O33: =SUM(O2:O32) -> 0 | Q33: =SUM(Q2:Q32) -> 0 | S33: =SUM(S2:S32) -> 0 | U33: =SUM(U2:U32) -> 0

Sheet Зайка
A1: март | B1: апрель | C1: май | D1: июнь | E1: октябрь | G1: ноябрь | I1: декабрь | K1: январь | M1: февраль | O1: март | Q1: апрель | S1: май | U1: июнь | W1: июль | Y1: август
A2: =7+5+54 -> 66 | B2: =4.84+11.98 -> 16.82 | E2: =15.82+4 -> 19.82 | G2: =39.9 -> 39.9
A3: =30.69+17.55 -> 48.24 | B3: =3 -> 3 | C3: =4 -> 4 | E3: =6.2+8 -> 14.2 | G3: =4 -> 4
C4: =8 -> 8 | E4: =4 -> 4
A5: =3+2.57 -> 5.57 | B5: =10.43+7+5.28 -> 22.71 | E5: =8 -> 8
A6: =7 -> 7
G7: =31.89 -> 31.89
B8: =3 -> 3 | E8: =8.12+4 -> 12.12
A9: =45 -> 45 | B9: =4.26 -> 4.26 | E9: =4 -> 4
E10: =4 -> 4
B11: =3 -> 3 | E11: =10.7+6.99+0.52 -> 18.21 | G11: =4 -> 4
E12: =8+6.62+5.9 -> 20.52 | G12: =4 -> 4
G13: =4 -> 4
G14: =4 -> 4
A16: =3 -> 3 | B16: 3 | E16: =18.75+3.99+5 -> 27.74 | G16: =4+3 -> 7
B17: 4.6
A18: =21.71 -> 21.71 | B18: 3 | E18: =4 -> 4 | G18: 8
A19: =3+6.8 -> 9.8 | C19: 7 | E19: =26.23 -> 26.23 | G19: =4.16+7+4+4 -> 19.16
C20: =2.7+35+40 -> 77.7 | G20: =1.89+4 -> 5.89
A21: =3 -> 3 | C21: =192+13.55 -> 205.55
A22: 7 | C22: =6.45+3 -> 9.45 | G22: =2.15+6.2 -> 8.35 | I22: =8.5 -> 8.5
C23: =3 -> 3 | G23: =5 -> 5
A24: 3 | C24: =3.9+3 -> 6.9 | G24: =4 -> 4
B25: =32.37 -> 32.37 | G25: =8 -> 8 | I25: =4 -> 4
B26: =3 -> 3 | C26: 7 | I26: =4 -> 4
B27: =3 -> 3 | I27: =6 -> 6
A28: =3 -> 3 | B28: =3 -> 3 | G28: =8 -> 8 | I28: =6 -> 6
A29: 3 | G29: =8 -> 8 | I29: =2.5 -> 2.5
A30: 7 | C30: =2 -> 2 | G30: =8 -> 8 | I30: =8.5+38.37 -> 46.87
A33: =SUM(A2:A32) -> 232.32 | B33: =SUM(B2:B32) -> 104.76 | C33: =SUM(C2:C32) -> 330.6 | D33: =SUM(D2:D32) -> 0 | E33: =SUM(E2:E32) -> 162.84 | G33: =SUM(G2:G32) -> 181.19 | I33: =SUM(I2:I32) -> 77.87 | K33: =SUM(K2:K32) -> 0 | M33: =SUM(M2:M32) -> 0 | O33: =SUM(O2:O32) -> 0 | Q33: =SUM(Q2:Q32) -> 0 | S33: =SUM(S2:S32) -> 0 | U33: =SUM(U2:U32) -> 0 | W33: =SUM(W2:W32) -> 0 | Y33: =SUM(Y2:Y32) -> 0

Sheet Вовчик
A1: март | B1: апрель | C1: май | D1: июнь | E1: октябрь | G1: ноябрь | I1: декабрь | K1: январь | M1: февраль | O1: март | Q1: апрель | S1: май | U1: июнь | W1: июль | Y1: август | AA1: сентябрь
C19: =31.3+18 -> 49.3
C20: =10.49 -> 10.49 | E20: =20+5+90+90+16+30+10 -> 261
G26: =14 -> 14
G27: 85
A33: =SUM(A2:A32) -> 0 | B33: =SUM(B2:B32) -> 0 | C33: =SUM(C2:C32) -> 59.79 | D33: =SUM(D2:D32) -> 0 | E33: =SUM(E2:E32) -> 261 | G33: =SUM(G2:G32) -> 99 | I33: =SUM(I2:I32) -> 0 | K33: =SUM(K2:K32) -> 0 | M33: =SUM(M2:M32) -> 0 | O33: =SUM(O2:O32) -> 0 | Q33: =SUM(Q2:Q32) -> 0 | S33: =SUM(S2:S32) -> 0 | U33: =SUM(U2:U32) -> 0 | W33: =SUM(W2:W32) -> 0 | Y33: =SUM(Y2:Y32) -> 0 | AA33: =SUM(AA2:AA32) -> 0

Sheet Непредвиденные
A1: март | B1: апрель | C1: май | D1: июнь | E1: октябрь | G1: ноябрь | I1: декабрь | K1: январь | M1: февраль | O1: март | Q1: апрель | S1: май | U1: июнь | W1: июль | Y1: август
B2: =24+9 -> 33
G3: =14 -> 14 | H3: стрижка
A6: =10+88.47+20 -> 118.47 | B6: 50.68
A7: =59.99+95.21+1.65+2.43+5.73+265 -> 430.01 | B7: =19.99 -> 19.99
G8: =0.82+1.14+1 -> 2.96
G11: =5+15 -> 20
B12: =6.03+23 -> 29.03
B13: =17.83 -> 17.83
B14: =15 -> 15
B15: =28.3 -> 28.3
A16: =55 -> 55
B17: =7.9 -> 7.9 | G17: =1.17+1.14+0.82 -> 3.13
A20: 2.24 | C20: 25
B23: 7.78
G26: =32 -> 32
G30: =482+40 -> 522 | H30: подарок тесть
A33: =SUM(A2:A32) -> 605.72 | B33: =SUM(B2:B32) -> 209.51 | C33: =SUM(C2:C32) -> 25 | D33: =SUM(D2:D32) -> 0 | E33: =SUM(E2:E32) -> 0 | G33: =SUM(G2:G32) -> 594.09 | I33: =SUM(I2:I32) -> 0 | K33: =SUM(K2:K32) -> 0 | M33: =SUM(M2:M32) -> 0 | O33: =SUM(O2:O32) -> 0 | Q33: =SUM(Q2:Q32) -> 0 | S33: =SUM(S2:S32) -> 0 | U33: =SUM(U2:U32) -> 0 | W33: =SUM(W2:W32) -> 0 | Y33: =SUM(Y2:Y32) -> 0

Sheet Машина 
A1: Вид ремонта | B1: Сумма | C1: Дата | D1: всего
A2: Замена салейнтблоков замена масла | B2: 700 | C2: 45301 | D2: =SUM(B$2:B$1048576) -> 4148
A3: Рулевые наконечники | B3: 120 | C3: 45337
A4: Генератор | B4: 610 | C4: 45348
A5: Лобовое стекло | B5: 300 | C5: 45366
A6: Замена масла | B6: 167 | C6: 45374
A7: Развал-схождения | B7: 40 | C7: 45392
A8: Ремонт левого супорта | B8: 126 | C8: 45397
A9: Замена шаровых, замена опоры преднего левого амортизатора, замена катушки зажигания | B9: 550 | C9: 45463
A10: Замена цепи ГРМ | B10: 855 | C10: 45483 | D10: 238 000 км
A11: Замена всех катушек, замена динамика, моторчик заднего стеклоомывателя, рычаг заднего стеклоомывателя | B11: =38+57+240+40 -> 375 | C11: 45498
A12: Замена свечей зажигания замена крышки заливной масла масло на долив | B12: 142.4 | C12: 45558
A13: Замена масла и фильтра | B13: 162.6 | C13: 45619
